Workbook

Sheet Hệ thống tổng hợp tài sản
A1: Mã tài sản | B1: Tên tài sản | C1: Vị trí | D1: Hãng mua | E1: Thông số kĩ thuật | F1: Mã số bảo hành | G1: Đơn vị tính | H1: Số lượng | I1: Mã nhân viên sử dụng gần nhất | J1: Họ tên nhân viên sử dụng gần nhất | K1: Bộ phận sử dụng gần nhất | L1: Ngày cấp | M1: Đơn vị mua | N1: Người sử dụng 1 | O1: Người sử dụng 2 | P1: Người sử dụng 3
H6: 2
H7: 2

Sheet Trang_tính1
A3: TÊN TÀI SẢN | B3: Tổng của SỐ LƯỢNG
A4: Bàn ban công | B4: 1
A5: Bàn đơn TBP | B5: 7
A6: Bàn gỗ có hộc | B6: 1
A7: Bàn gỗ không hộc | B7: 1
A8: Bàn làm việc mặt gỗ | B8: 2
A9: Bàn làm việc mặt kính | B9: 11
A10: Bàn làm việc TGD | B10: 1
A11: Bàn phòng họp (dài) | B11: 1
A12: Bàn phòng họp (ngắn) | B12: 6
A13: Bàn tiếp khách mặt cong (màu trắng) | B13: 1
A14: Bàn tiếp khách tròn mặt kính | B14: 1
A15: Bàn tròn trơn mặt gỗ (Màu trắng) | B15: 1
... A18: Camera | B18: 10
A19: Camera chiếu tivi
A20: Cây nước (Nóng/lạnh) | B20: 1
A21: Đầu ghi | B21: 2
A22: Ghế 4 chân | B22: 12
A23: Ghế ban công | B23: 6
A24: Ghế băng dài | B24: 1
A25: Ghế chân quỳ | B25: 9
A26: Ghế gấp | B26: 14
A27: Ghế làm việc TGĐ | B27: 1
A28: Ghế sofa | B28: 1
A29: Ghế TBP - màu đen | B29: 2
A30: Ghế TBP - màu trắng | B30: 8
A31: Ghế tiếp khách | B31: 1
... A49: Tủ lạnh | B49: 1
A50: (trống)
A51: Tổng Cuối | B51: 182

Sheet TỔNG HỢP TS
A2: LOẠI TÀI SẢN | B2: THÁNG 08.2026 | F2: THÁNG 09.2026 | J2: THÁNG 10.2026 | N2: THÁNG 11.2026 | R2: THÁNG 12.2026
B3: ĐẦU KÌ | C3: TĂNG TRONG KÌ | D3: GIẢM TRONG KÌ | E3: CUỐI KÌ | F3: ĐẦU KÌ | G3: TĂNG TRONG KÌ | H3: GIẢM TRONG KÌ | I3: CUỐI KÌ | J3: ĐẦU KÌ | K3: TĂNG TRONG KÌ | L3: GIẢM TRONG KÌ | M3: CUỐI KÌ | N3: ĐẦU KÌ | O3: TĂNG TRONG KÌ | P3: GIẢM TRONG KÌ | Q3: CUỐI KÌ | R3: ĐẦU KÌ | S3: TĂNG TRONG KÌ | T3: GIẢM TRONG KÌ | U3: CUỐI KÌ
A4: Laptop
A5: PC
A6: Màn hình máy tính
A7: Chuột
A8: Bàn phím
A9: Ổ cứng

Sheet 01. Tài sản tăng
C1: Hanoi Head Office: 3rd Floor., 69 Building, Nguyen Hy Quang Str., Dong Da Dist., Hanoi, Vietnam Tel + 84 24 3715 3303 / 3927 5600 / Fax + 84 24 3627 6563 HCM Branch Office: 2nd Floor, Ha Do Airport Building - 02 Hong Ha St.,Tan Binh Dist, HCM City, Vietnam Tel + 84 28 222 16328 Website: newdaymedia.com.vn
A2: THEO DÕI TÀI SẢN TĂNG | D2: - Mã PC trống mã : PC053, PC054 - Mã Chuột trống: CH053, CH054 - Mã Bàn phím trống : BP053 BP054
A3: STT | B3: LOẠI TÀI SẢN | C3: MÃ TÀI SẢN | D3: TÊN TÀI SẢN | E3: THÔNG SỐ KĨ THUẬT | F3: ĐƠN VỊ | G3: SỐ LƯỢNG | H3: NGÀY MUA | I3: GIÁ MUA | J3: MNV NGƯỜI ĐỀ XUẤT | K3: HỌ TÊN NGƯỜI ĐỀ XUẤT | L3: BỘ PHẬN ĐỀ XUẤT | M3: MNV NGƯỜI SỬ DỤNG | N3: NGƯỜI SỬ DỤNG | O3: NHÓM NCC | P3: ĐƠN VỊ CUNG CẤP | Q3: SĐT KÍCH HOẠT BẢO HÀNH | R3: SĐT NCC | S3: LINK PHIẾU BẢO HÀNH | T3: MÃ THANH TOÁN | U3: HC THEO DÕI THÔNG TIN | V3: GHI CHÚ
A4: NĂM 2025
A5: 1 | B5: TS máy móc thiết bị | D5: Laptop HP 250 | F5: Chiếc | G5: 1 | H5: 45876 | I5: 13930000 | K5: Nguyễn Hồng Nhung | L5: Tài chính & Kế toán - Finance & Accounting | M5: 25022 | N5: Nguyễn Hồng Nhung | O5: Đồ điện tử | P5: CellphoneS | Q5: 0779262715 | T5: 070825-02 | U5: Ngô Thị Hồng Hải
A6: 2 | B6: TS máy móc thiết bị | C6: PC031 | D6: PC | F6: Chiếc | G6: 1 | H6: 45888 | I6: 30500000 | J6: 20001 | K6: Hoàng Quốc Nghị | L6: Thiết kế - Design | M6: 25029 | N6: Đinh Ngọc Thành | O6: Đồ điện tử | P6: Hoàng Hà | Q6: 0779262715 | S6: Phiếu BH | T6: 996202 | U6: Ngô Thị Hồng Hải
A7: 3 | B7: TS máy móc thiết bị | C7: MH031 | D7: Màn hình máy tính | F7: Chiếc | G7: 1 | H7: 45888 | J7: 20001 | K7: Hoàng Quốc Nghị | L7: Thiết kế - Design | M7: 25029 | N7: Đinh Ngọc Thành | O7: Đồ điện tử | P7: Hoàng Hà | Q7: 0779262715 | U7: Ngô Thị Hồng Hải
A8: 4 | B8: TS máy móc thiết bị | C8: CH031 | D8: Chuột | F8: Chiếc | G8: 1 | H8: 45888 | J8: 20001 | K8: Hoàng Quốc Nghị | L8: Thiết kế - Design | M8: 25029 | N8: Đinh Ngọc Thành | O8: Đồ điện tử | P8: Hoàng Hà | Q8: 0779262715 | U8: Ngô Thị Hồng Hải
A9: 5 | B9: TS máy móc thiết bị | C9: MH047 | D9: Màn hình máy tính | F9: Chiếc | G9: 1 | H9: 45917 | I9: 91568000 | J9: 22003 | K9: Nguyễn Thành Long | L9: Sản xuất Video - Video Prodution | M9: 25011 | N9: Lê Công Hoàng | O9: Đồ điện tử | P9: An phát | Q9: 0779262715 | S9: Phiếu BH | T9: 1046211 | U9: Ngô Thị Hồng Hải
A10: 6 | B10: TS máy móc thiết bị | C10: PC047 | D10: PC | F10: Chiếc | G10: 1 | H10: 45917 | J10: 22003 | K10: Nguyễn Thành Long | L10: Sản xuất Video - Video Prodution | M10: 25011 | N10: Lê Công Hoàng | O10: Đồ điện tử | P10: An phát | Q10: 0779262715 | U10: Ngô Thị Hồng Hải
A11: 7 | B11: TS máy móc thiết bị | C11: MH048 | D11: Màn hình máy tính | F11: Chiếc | G11: 1 | H11: 45917 | J11: 22003 | K11: Nguyễn Thành Long | L11: Sản xuất Video - Video Prodution | M11: 25011 | N11: Lê Công Hoàng | O11: Đồ điện tử | P11: An phát | Q11: 0779262715 | U11: Ngô Thị Hồng Hải
A12: 8 | B12: TS máy móc thiết bị | C12: MH043 | D12: Màn hình máy tính | F12: Chiếc | G12: 1 | H12: 45917 | J12: 22003 | K12: Nguyễn Thành Long | L12: Sản xuất Video - Video Prodution | M12: 25032 | N12: Nguyễn Ngọc Thắng | O12: Đồ điện tử | P12: An phát | Q12: 0779262715 | U12: Ngô Thị Hồng Hải
A13: 9 | B13: TS máy móc thiết bị | C13: PC050 | D13: PC | F13: Chiếc | G13: 1 | H13: 45931 | I13: 25060000 | J13: 22001 | K13: Bùi Xuân Dân | L13: Sự kiện - Event | M13: 22001 | N13: Bùi Xuân Dân | O13: Đồ điện tử | P13: Nguyễn Công | Q13: 0779262715 | S13: Phiếu BH | T13: 1066566 | U13: Ngô Thị Hồng Hải
A14: 10 | B14: TS máy móc thiết bị | C14: MH050 | D14: Màn hình máy tính | F14: Chiếc | G14: 1 | H14: 45931 | J14: 22002 | K14: Bùi Xuân Dân | L14: Sự kiện - Event | M14: 22001 | N14: Bùi Xuân Dân | O14: Đồ điện tử | P14: Nguyễn Công | Q14: 0779262715 | U14: Ngô Thị Hồng Hải
A15: 11 | B15: TS máy móc thiết bị | C15: CAM001 | D15: Bộ thiết bị cam | F15: Bộ | G15: 1 | H15: 45962 | I15: 18700000 | J15: 22003 | K15: Nguyễn Thành Long | L15: Sản xuất Video - Video Prodution | M15: 22003 | N15: Nguyễn Thành Long | O15: Đồ điện tử | P15: Tokyo | Q15: 0779262715 | S15: Phiếu BH | T15: 1129720 | U15: Ngô Thị Hồng Hải | V15: LINK
A16: 12 | B16: TS máy móc thiết bị | C16: MH051 | D16: Màn hình máy tính | F16: Chiếc | G16: 1 | H16: 46006 | I16: 88750000 | J16: 22003 | K16: Nguyễn Thành Long | L16: Sản xuất Video - Video Prodution | M16: 25045 | N16: Nguyễn Anh Tuấn | O16: Đồ điện tử | P16: Nguyễn Công | Q16: 0779262715 | S16: Phiếu BH | T16: 1226115 | U16: Ngô Thị Hồng Hải
A17: 13 | B17: TS máy móc thiết bị | C17: MH053 | D17: Màn hình máy tính | F17: Chiếc | G17: 1 | H17: 46006 | J17: 22003 | K17: Nguyễn Thành Long | L17: Sản xuất Video - Video Prodution | M17: 25045 | N17: Nguyễn Anh Tuấn | O17: Đồ điện tử | P17: Nguyễn Công | Q17: 0779262715 | U17: Ngô Thị Hồng Hải
A18: 14 | B18: TS máy móc thiết bị | C18: PC051 | D18: PC | F18: Chiếc | G18: 1 | H18: 46006 | J18: 22003 | K18: Nguyễn Thành Long | L18: Sản xuất Video - Video Prodution | M18: 25045 | N18: Nguyễn Anh Tuấn | O18: Đồ điện tử | P18: Nguyễn Công | Q18: 0779262715 | U18: Ngô Thị Hồng Hải
A19: 15 | B19: TS máy móc thiết bị | C19: BP051 | D19: Bàn phím | F19: Chiếc | G19: 1 | H19: 46006 | J19: 22003 | K19: Nguyễn Thành Long | L19: Sản xuất Video - Video Prodution | M19: 25045 | N19: Nguyễn Anh Tuấn | O19: Đồ điện tử | P19: Nguyễn Công | Q19: 0779262715 | U19: Ngô Thị Hồng Hải
A20: 16 | B20: TS máy móc thiết bị | C20: CH051 | D20: Chuột | F20: Chiếc | G20: 1 | H20: 46006 | J20: 22003 | K20: Nguyễn Thành Long | L20: Sản xuất Video - Video Prodution | M20: 25045 | N20: Nguyễn Anh Tuấn | O20: Đồ điện tử | P20: Nguyễn Công | Q20: 0779262715 | U20: Ngô Thị Hồng Hải
A21: 17 | B21: TS máy móc thiết bị | C21: MH052 | D21: Màn hình máy tính | F21: Chiếc | G21: 1 | H21: 46006 | I21: 88750000 | J21: 22003 | K21: Nguyễn Thành Long | L21: Sản xuất Video - Video Prodution | M21: 25046 | N21: Phùng Vân Anh | O21: Đồ điện tử | P21: Nguyễn Công | Q21: 0779262715 | U21: Ngô Thị Hồng Hải
A22: 18 | B22: TS máy móc thiết bị | C22: MH054 | D22: Màn hình máy tính | F22: Chiếc | G22: 1 | H22: 46006 | J22: 22003 | K22: Nguyễn Thành Long | L22: Sản xuất Video - Video Prodution | M22: 25046 | N22: Phùng Vân Anh | O22: Đồ điện tử | P22: Nguyễn Công | Q22: 0779262715 | U22: Ngô Thị Hồng Hải
A23: 19 | B23: TS máy móc thiết bị | C23: PC052 | D23: PC | F23: Chiếc | G23: 1 | H23: 46006 | J23: 22003 | K23: Nguyễn Thành Long | L23: Sản xuất Video - Video Prodution | M23: 25046 | N23: Phùng Vân Anh | O23: Đồ điện tử | P23: Nguyễn Công | Q23: 0779262715 | U23: Ngô Thị Hồng Hải
A24: 20 | B24: TS máy móc thiết bị | C24: BP052 | D24: Bàn phím | F24: Chiếc | G24: 1 | H24: 46006 | J24: 22003 | K24: Nguyễn Thành Long | L24: Sản xuất Video - Video Prodution | M24: 25046 | N24: Phùng Vân Anh | O24: Đồ điện tử | P24: Nguyễn Công | Q24: 0779262715 | U24: Ngô Thị Hồng Hải
A25: 21 | B25: TS máy móc thiết bị | C25: CH052 | D25: Chuột | F25: Chiếc | G25: 1 | H25: 46006 | J25: 22003 | K25: Nguyễn Thành Long | L25: Sản xuất Video - Video Prodution | M25: 25046 | N25: Phùng Vân Anh | O25: Đồ điện tử | P25: Nguyễn Công | Q25: 0779262715 | U25: Ngô Thị Hồng Hải
A26: NĂM 2026
A27: 1 | B27: TS máy móc thiết bị | C27: OC-009 | D27: Ổ cứng | F27: Chiếc | G27: 1 | H27: 46048 | I27: 1750000 | J27: 25037 | K27: Trần Thị Huyền | L27: Hành chính nhân sự - HR & Admin | N27: Đặng Đức Hoàng | O27: Đồ điện tử | P27: Công ty Cổ phần máy tính H2 | T27: 25037 | U27: Trần Thị Huyền
A28: 2 | B28: TS máy móc thiết bị | C28: OC-010 | D28: Ổ cứng | F28: Chiếc | G28: 1 | H28: 46059 | I28: 5333333 | J28: 25037 | K28: Trần Thị Huyền | L28: Hành chính nhân sự - HR & Admin | N28: Nguyễn Thị Thu Hoài | O28: Đồ điện tử | T28: 25037 | U28: Trần Thị Huyền
A29: 3 | B29: TS máy móc thiết bị | C29: OC-011 | D29: Ổ cứng | F29: Chiếc | G29: 1 | H29: 46059 | I29: 8425926 | J29: 25037 | K29: Trần Thị Huyền | L29: Hành chính nhân sự - HR & Admin | N29: Nguyễn Ngọc Thắng | O29: Đồ điện tử | T29: 25037 | U29: Trần Thị Huyền
A30: 4 | B30: TS máy móc thiết bị | C30: OC-012 | D30: Ổ cứng | E30: - HDD | F30: Chiếc | G30: 1 | H30: 46059 | I30: 11666667 | J30: 25037 | K30: Trần Thị Huyền | L30: Hành chính nhân sự - HR & Admin | N30: Nguyễn Ngọc Thắng | O30: Đồ điện tử | T30: 25037 | U30: Trần Thị Huyền
A31: 5 | B31: TS máy móc thiết bị | C31: RAM01 | D31: Ổ cứng | F31: Chiếc | G31: 1 | H31: 46059 | I31: 5203704 | J31: 25037 | K31: Trần Thị Huyền | L31: Hành chính nhân sự - HR & Admin | N31: Nguyễn Ngọc Thắng | O31: Đồ điện tử | T31: 25037 | U31: Trần Thị Huyền
A32: 6 | B32: TS máy móc thiết bị | C32: OC-007 | D32: Ổ cứng | F32: Chiếc | G32: 1 | H32: 46090 | I32: 1900000 | J32: 26004 | K32: Nguyễn Mai Hương | L32: Hành chính nhân sự - HR & Admin | N32: Nguyễn Mạnh Hoàng | O32: Đồ điện tử | P32: Công ty Cổ phần máy tính H2 | T32: 1363358 | U32: Nguyễn Mai Hương
A33: 7 | B33: TS máy móc thiết bị | C33: BP06 | D33: Bàn phím | F33: Chiếc | G33: 1 | H33: 46090 | I33: 3000000 | J33: 26004 | K33: Nguyễn Mai Hương | L33: Hành chính nhân sự - HR & Admin | N33: Nguyễn Mạnh Hoàng | O33: Đồ điện tử | P33: Công ty Cổ phần máy tính H2 | T33: 1363358 | U33: Nguyễn Mai Hương
A34: 8 | B34: TS máy móc thiết bị | C34: SAC_01 | D34: Sạc Surface | E34: 102w | F34: Chiếc | G34: 1 | H34: 46120 | I34: 1350000 | J34: 26004 | K34: Nguyễn Mai Hương | L34: Hành chính nhân sự - HR & Admin | N34: Nguyễn Chí Hiếu | O34: Đồ điện tử | P34: Công ty TNHH Thương mại và Dịch vụ Trí Tiến | Q34: 0915129837 | T34: 1415811 | U34: Nguyễn Mai Hương
A35: 9 | B35: TS máy móc thiết bị | C35: LT004 | D35: Máy tính Surface Pro11 | F35: Chiếc | G35: 1 | H35: 46183 | I35: 47520000 | J35: 26016 | K35: Nguyễn Ngọc Huyền | L35: Hành chính nhân sự - HR & Admin | N35: Nguyễn Mạnh Hoàng | O35: Đồ điện tử | P35: Công ty TNHH Thương mại và Dịch vụ Trí Tiến | Q35: 02437153303 | R35: 0986981616 | S35: 1517945_Phiếu bảo hành SurfacePro11 phòng Creative.pdf | T35: 1517945 | U35: Nguyễn Ngọc Huyền
A36: 10 | B36: TS máy móc thiết bị | C36: BP036 | D36: Bàn phím | F36: Chiếc | G36: 1 | H36: 46183 | I36: 4320000 | J36: 26016 | K36: Nguyễn Ngọc Huyền | L36: Hành chính nhân sự - HR & Admin | N36: Nguyễn Mạnh Hoàng | O36: Đồ điện tử | P36: Công ty TNHH Thương mại và Dịch vụ Trí Tiến | Q36: 02437153303 | R36: 0986981616 | T36: 1539304 | U36: Nguyễn Ngọc Huyền
A37: 11 | B37: TS máy móc thiết bị | C37: PC055 | D37: PC | F37: Chiếc | G37: 1 | H37: 46190 | I37: 55280000 | J37: 26016 | K37: Nguyễn Ngọc Huyền | L37: Hành chính nhân sự - HR & Admin | M37: 26017 | N37: Nguyễn Duy Hưng | O37: Đồ điện tử | P37: Nguyễn Công | Q37: 0779262715 | R37: 0332101130 | S37: 1530844_Phiếu xuất kho, bảo hành PC - Duy Hưng P.Thiết kế | T37: 1530844 | U37: Nguyễn Ngọc Huyền
C38: MH055 | D38: Màn hình máy tính | F38: Chiếc | G38: 1 | I38: 5200000
C39: CH055 | D39: Chuột | F39: Chiếc | G39: 1 | I39: 0
C40: BP055 | D40: Bàn phím | F40: Chiếc | G40: 1 | I40: 0
...

Sheet 02. Tài sản giảm
C1: Hanoi Head Office: 80 Nguyen Chi Thanh St., Lang Ward, Hanoi, Vietnam. Tel: + 84 24 3715 3303 / Hotline: +84 904 033 333/ 096 2577770 Website: newdaymedia.com.vn Email: info@newdaymedia.com.vn Facebook: Newday Media JSC
A2: THEO DÕI TÀI SẢN GIẢM
A3: STT | B3: LOẠI TÀI SẢN | C3: MÃ TÀI SẢN | D3: TÊN TÀI SẢN | E3: LOẠI GIẢM | F3: ĐÁNH GIÁ TRẠNG THÁI | G3: NGÀY GIẢM TS | H3: GIÁ THANH LÝ | I3: HOÀN CHI PHÍ | J3: HC THEO DÕI THÔNG TIN | K3: GHI CHÚ
A4: 1 | B4: TS máy móc thiết bị | C4: MH036 | D4: MÀN HÌNH MÁY TÍNH | E4: Bán thanh lý | F4: Màn hỏng | G4: 46127 | H4: 30 | I4: 30 | J4: Ngô Thị Hồng Hải
A5: 2 | B5: TS máy móc thiết bị | C5: MH044 | D5: MÀN HÌNH MÁY TÍNH | E5: Bán thanh lý | F5: Màn hỏng | G5: 46127 | H5: 30 | I5: 30 | J5: Ngô Thị Hồng Hải
A6: 3 | B6: TS máy móc thiết bị | C6: PC014 | D6: PC | E6: Bán thanh lý | F6: PC cũ, lâu đời bị yếu | G6: 46127 | H6: 1,000,000 | I6: 1,000,000 | J6: Ngô Thị Hồng Hải
A7: 4 | B7: TS máy móc thiết bị | C7: PC017 | D7: PC | E7: Bán thanh lý | F7: PC cũ, lâu đời bị yếu | G7: 46127 | H7: 1,000,000 | I7: 1,000,000 | J7: Ngô Thị Hồng Hải
A8: 5 | B8: TS máy móc thiết bị | C8: PC033 | D8: PC | E8: Bán thanh lý | F8: PC cũ, lâu đời bị yếu | G8: 46127 | H8: 1,000,000 | I8: 1,000,000 | J8: Ngô Thị Hồng Hải
A9: 6 | B9: TS máy móc thiết bị | C9: PC034 | D9: PC | E9: Bán thanh lý | F9: PC cũ, lâu đời bị yếu | G9: 46127 | H9: 1,000,000 | I9: 1,000,000 | J9: Ngô Thị Hồng Hải
A10: 7 | B10: TS máy móc thiết bị | C10: PC003 | D10: PC | E10: Bán thanh lý | F10: PC cũ, lâu đời bị yếu | G10: 46212 | H10: 1000000 | I10: 1000000 | J10: Nguyễn Ngọc Huyền
A11: 8 | B11: TS máy móc thiết bị | C11: PC007 | D11: PC | E11: Bán thanh lý | F11: PC cũ, lâu đời bị yếu | G11: 46212 | H11: 1500000 | I11: 1500000 | J11: Nguyễn Ngọc Huyền
A12: 9 | B12: TS máy móc thiết bị | C12: PC012 | D12: PC | E12: Bán thanh lý | F12: PC cũ, lâu đời bị yếu | G12: 46212 | H12: 1500000 | I12: 1500000 | J12: Nguyễn Ngọc Huyền
A13: 10 | B13: TS máy móc thiết bị | C13: PC013 | D13: PC | E13: Bán thanh lý | F13: PC cũ, lâu đời bị yếu | G13: 46212 | H13: 1500000 | I13: 1500000 | J13: Nguyễn Ngọc Huyền
A14: 11 | B14: TS máy móc thiết bị | C14: PC022 | D14: PC | E14: Bán thanh lý | F14: PC cũ, lâu đời bị yếu | G14: 46212 | H14: 1500000 | I14: 1500000 | J14: Nguyễn Ngọc Huyền
A15: 12 | B15: TS máy móc thiết bị | C15: PC001 | D15: PC | E15: Bán thanh lý | F15: PC cũ, lâu đời bị yếu | G15: 46212 | H15: 1500000 | I15: 1500000 | J15: Nguyễn Ngọc Huyền
A16: 13 | B16: TS máy móc thiết bị | C16: PC032 | D16: PC | E16: Bán thanh lý | F16: PC cũ, lâu đời bị yếu | G16: 46212 | H16: 1500000 | I16: 1500000 | J16: Nguyễn Ngọc Huyền
A17: 13 | B17: TS máy móc thiết bị | C17: OC-002 | D17: Ổ cứng | E17: Trả file khách | F17: Dùng tốt | G17: 46296 | K17: Anh Nguyễn Thành Long trả file khách hàng Minh Ngọc
A18: 15
A19: 16
A20: 17
A21: 18
A22: 19
A23: 20
A24: 21
A25: 22

Sheet 03. Chi tiết TS các bộ phận
C1: Hanoi Head Office: 80 Nguyen Chi Thanh St., Lang Ward, Hanoi, Vietnam. Tel: + 84 24 3715 3303 / Hotline: +84 904 033 333/ 096 2577770 Website: newdaymedia.com.vn Email: info@newdaymedia.com.vn Facebook: Newday Media JSC
A2: THEO DÕI TÀI SẢN MÁY MÓC THIẾT BỊ | H2: Laptop | I2: PC | J2: Màn hình máy tính | K2: Chuột | L2: Bàn phím | M2: Ổ cứng | N2: Khác | R2: Mã NV - Nguyễn Văn A - Sử dụng từ...đến...., bàn giao lại HCNS ngày....
H3: =COUNTIF(B:B, "Laptop") -> 7 | I3: =COUNTIF(B:B, "PC") -> 40 | J3: =COUNTIF(B:B, "Màn hình máy tính") -> 55 | K3: =COUNTIF(B:B, "Chuột ") -> 35 | L3: =COUNTIF(B:B, "Bàn phím") -> 33 | M3: =COUNTIF(B:B, "Ổ cứng") -> 11 | N3: =COUNTIF(A:A, "khác") -> 6
A5: MÃ TS | B5: TÊN TÀI SẢN | C5: HÃNG MUA | D5: THÔNG SỐ KĨ THUẬT | E5: VỊ TRÍ | F5: ĐƠN VỊ TÍNH | G5: SỐ LƯỢNG | H5: MÃ NHÂN VIÊN ĐANG SD | I5: HỌ TÊN NHÂN VIÊN ĐANG SD | J5: BỘ PHẬN | K5: TRẠNG THÁI NHÂN VIÊN ĐANG SD | L5: MÃ BIÊN BẢN BÀN GIAO | M5: NGÀY KÝ BBBG | N5: NGÀY CẤP THIẾT BỊ | O5: TRẠNG THÁI TÀI SẢN | P5: MÃ SỐ BẢO HÀNH | Q5: GHI CHÚ | R5: NGƯỜI SỬ DỤNG 1 | S5: NGƯỜI SỬ DỤNG 2 | T5: NGƯỜI SỬ DỤNG 3 | U5: NGƯỜI SỬ DỤNG 4 | V5: NGƯỜI SỬ DỤNG 5
A6: I. SẢN XUẤT VIDEO - VIDEO PRODUTION | M6: `
A7: PC010 | B7: PC | D7: - Chip: AMD Ryzen 9 9900X 12-Core Processor - Ram: 128 GB - Card màn hình: 18 GB - Ổ cứng: 5.46 TB | E7: Khu vực BP Video | F7: Cái | G7: 1 | H7: 24004 | I7: =INDEX('6. data thông tin nhân sự'!C:C,MATCH('03. Chi tiết TS các bộ phận'!H7,'6. data thông tin nhân sự'!B:B,0)) -> Vũ Anh Duy | J7: =INDEX('6. data thông tin nhân sự'!G:G,MATCH('03. Chi tiết TS các bộ phận'!H7,'6. data thông tin nhân sự'!B:B,0)) -> Sản xuất Video - Video Prodution | K7: =INDEX('6. data thông tin nhân sự'!D:D,MATCH('03. Chi tiết TS các bộ phận'!H7,'6. data thông tin nhân sự'!B:B,0)) -> Chính thức | L7: VD_02 | M7: 46202 | N7: =INDEX('6. data thông tin nhân sự'!N:N, MATCH('03. Chi tiết TS các bộ phận'!H7, '6. data thông tin nhân sự'!B:B,0)) -> 04/04/2024 | O7: Đang sử dụng
A8: MH051 | B8: Màn hình máy tính | C8: Dell | E8: Khu vực BP Video | F8: Cái | G8: 1 | H8: 24004 | I8: =INDEX('6. data thông tin nhân sự'!C:C,MATCH('03. Chi tiết TS các bộ phận'!H8,'6. data thông tin nhân sự'!B:B,0)) -> Vũ Anh Duy | J8: =INDEX('6. data thông tin nhân sự'!G:G,MATCH('03. Chi tiết TS các bộ phận'!H8,'6. data thông tin nhân sự'!B:B,0)) -> Sản xuất Video - Video Prodution | K8: =INDEX('6. data thông tin nhân sự'!D:D,MATCH('03. Chi tiết TS các bộ phận'!H8,'6. data thông tin nhân sự'!B:B,0)) -> Chính thức | M8: 46202 | N8: 46006 | O8: Đang sử dụng | P8: Phiếu BH | Q8: Sử dung MH010 và MH040 đến ngày 15/12 bàn giao cho Tuấn - Video
A9: MH053 | B9: Màn hình máy tính | C9: Dell | E9: Khu vực BP Video | F9: Cái | G9: 1 | H9: 24004 | I9: =INDEX('6. data thông tin nhân sự'!C:C,MATCH('03. Chi tiết TS các bộ phận'!H9,'6. data thông tin nhân sự'!B:B,0)) -> Vũ Anh Duy | J9: =INDEX('6. data thông tin nhân sự'!G:G,MATCH('03. Chi tiết TS các bộ phận'!H9,'6. data thông tin nhân sự'!B:B,0)) -> Sản xuất Video - Video Prodution | K9: =INDEX('6. data thông tin nhân sự'!D:D,MATCH('03. Chi tiết TS các bộ phận'!H9,'6. data thông tin nhân sự'!B:B,0)) -> Chính thức | M9: 46202 | N9: 46006 | O9: Đang sử dụng
A10: CH010 | B10: Chuột | E10: Khu vực BP Video | F10: Cái | G10: 1 | H10: 24004 | I10: =INDEX('6. data thông tin nhân sự'!C:C,MATCH('03. Chi tiết TS các bộ phận'!H10,'6. data thông tin nhân sự'!B:B,0)) -> Vũ Anh Duy | J10: =INDEX('6. data thông tin nhân sự'!G:G,MATCH('03. Chi tiết TS các bộ phận'!H10,'6. data thông tin nhân sự'!B:B,0)) -> Sản xuất Video - Video Prodution | K10: =INDEX('6. data thông tin nhân sự'!D:D,MATCH('03. Chi tiết TS các bộ phận'!H10,'6. data thông tin nhân sự'!B:B,0)) -> Chính thức | M10: 46202 | N10: =INDEX('6. data thông tin nhân sự'!N:N, MATCH('03. Chi tiết TS các bộ phận'!H10, '6. data thông tin nhân sự'!B:B,0)) -> 04/04/2024 | O10: Đang sử dụng
A11: PC011 | B11: PC | D11: - Chip: 12th Gen Intel(R) Core(TM) i9-12900K - Ram: 32 GB - Card màn hình: 12 GB - Ổ cứng: 15,01 TB | E11: Khu vực BP Video | F11: Cái | G11: 1 | H11: 25026 | I11: =INDEX('6. data thông tin nhân sự'!C:C,MATCH('03. Chi tiết TS các bộ phận'!H11,'6. data thông tin nhân sự'!B:B,0)) -> Vũ Hoàng Duy | J11: =INDEX('6. data thông tin nhân sự'!G:G,MATCH('03. Chi tiết TS các bộ phận'!H11,'6. data thông tin nhân sự'!B:B,0)) -> Sản xuất Video - Video Prodution | K11: =INDEX('6. data thông tin nhân sự'!D:D,MATCH('03. Chi tiết TS các bộ phận'!H11,'6. data thông tin nhân sự'!B:B,0)) -> Chính thức | L11: VD_03 | M11: 46204 | N11: =INDEX('6. data thông tin nhân sự'!N:N, MATCH('03. Chi tiết TS các bộ phận'!H11, '6. data thông tin nhân sự'!B:B,0)) -> 30/07/2025 | O11: Đang sử dụng
A12: MH052 | B12: Màn hình máy tính | C12: Asus LCD | E12: Khu vực BP Video | F12: Cái | G12: 1 | H12: 25026 | I12: =INDEX('6. data thông tin nhân sự'!C:C,MATCH('03. Chi tiết TS các bộ phận'!H12,'6. data thông tin nhân sự'!B:B,0)) -> Vũ Hoàng Duy | J12: =INDEX('6. data thông tin nhân sự'!G:G,MATCH('03. Chi tiết TS các bộ phận'!H12,'6. data thông tin nhân sự'!B:B,0)) -> Sản xuất Video - Video Prodution | K12: =INDEX('6. data thông tin nhân sự'!D:D,MATCH('03. Chi tiết TS các bộ phận'!H12,'6. data thông tin nhân sự'!B:B,0)) -> Chính thức | M12: 46204 | N12: 46006 | O12: Đang sử dụng | P12: Phiếu BH | Q12: Sử dung MH011 và MH009 đến ngày 15/12 bàn giao cho Vân Anh - Video
A13: MH054 | B13: Màn hình máy tính | C13: Asus LCD | E13: Khu vực BP Video | F13: Cái | G13: 1 | H13: 25026 | I13: =INDEX('6. data thông tin nhân sự'!C:C,MATCH('03. Chi tiết TS các bộ phận'!H13,'6. data thông tin nhân sự'!B:B,0)) -> Vũ Hoàng Duy | J13: =INDEX('6. data thông tin nhân sự'!G:G,MATCH('03. Chi tiết TS các bộ phận'!H13,'6. data thông tin nhân sự'!B:B,0)) -> Sản xuất Video - Video Prodution | K13: =INDEX('6. data thông tin nhân sự'!D:D,MATCH('03. Chi tiết TS các bộ phận'!H13,'6. data thông tin nhân sự'!B:B,0)) -> Chính thức | M13: 46204 | N13: 46006 | O13: Đang sử dụng
A14: BP011 | B14: Bàn phím | E14: Khu vực BP Video | F14: Cái | G14: 1 | H14: 25026 | I14: =INDEX('6. data thông tin nhân sự'!C:C,MATCH('03. Chi tiết TS các bộ phận'!H14,'6. data thông tin nhân sự'!B:B,0)) -> Vũ Hoàng Duy | J14: =INDEX('6. data thông tin nhân sự'!G:G,MATCH('03. Chi tiết TS các bộ phận'!H14,'6. data thông tin nhân sự'!B:B,0)) -> Sản xuất Video - Video Prodution | K14: =INDEX('6. data thông tin nhân sự'!D:D,MATCH('03. Chi tiết TS các bộ phận'!H14,'6. data thông tin nhân sự'!B:B,0)) -> Chính thức | M14: 46204 | N14: =INDEX('6. data thông tin nhân sự'!N:N, MATCH('03. Chi tiết TS các bộ phận'!H14, '6. data thông tin nhân sự'!B:B,0)) -> 30/07/2025 | O14: Đang sử dụng
A15: PC047 | B15: PC | D15: - AMD Ryzen 9 9950X 16-Core Processor - Ram: 128 GB - Card màn hình: 16 GB - Ổ cứng: 7,28 TB | E15: Khu vực BP Video | F15: Cái | G15: 1 | H15: 25011 | I15: =INDEX('6. data thông tin nhân sự'!C:C,MATCH('03. Chi tiết TS các bộ phận'!H15,'6. data thông tin nhân sự'!B:B,0)) -> Lê Công Hoàng | J15: =INDEX('6. data thông tin nhân sự'!G:G,MATCH('03. Chi tiết TS các bộ phận'!H15,'6. data thông tin nhân sự'!B:B,0)) -> Sản xuất Video - Video Prodution | K15: =INDEX('6. data thông tin nhân sự'!D:D,MATCH('03. Chi tiết TS các bộ phận'!H15,'6. data thông tin nhân sự'!B:B,0)) -> Chính thức | L15: VD_04 | M15: 46204 | N15: 45917 | O15: Đang sử dụng | P15: Phiếu BH | Q15: PC047 - mới mua ngày. 17/09/2025
A16: MH047 | B16: Màn hình máy tính | C16: Asus Pro | E16: Khu vực BP Video | F16: Cái | G16: 1 | H16: 25011 | I16: =INDEX('6. data thông tin nhân sự'!C:C,MATCH('03. Chi tiết TS các bộ phận'!H16,'6. data thông tin nhân sự'!B:B,0)) -> Lê Công Hoàng | J16: =INDEX('6. data thông tin nhân sự'!G:G,MATCH('03. Chi tiết TS các bộ phận'!H16,'6. data thông tin nhân sự'!B:B,0)) -> Sản xuất Video - Video Prodution | K16: =INDEX('6. data thông tin nhân sự'!D:D,MATCH('03. Chi tiết TS các bộ phận'!H16,'6. data thông tin nhân sự'!B:B,0)) -> Chính thức | M16: 46204 | N16: 45917 | O16: Đang sử dụng | Q16: MH047 - mới mua ngày 17/09/2025
A17: MH048 | B17: Màn hình máy tính | C17: Asus Pro | E17: Khu vực BP Video | F17: Cái | G17: 1 | H17: 25011 | I17: =INDEX('6. data thông tin nhân sự'!C:C,MATCH('03. Chi tiết TS các bộ phận'!H17,'6. data thông tin nhân sự'!B:B,0)) -> Lê Công Hoàng | J17: =INDEX('6. data thông tin nhân sự'!G:G,MATCH('03. Chi tiết TS các bộ phận'!H17,'6. data thông tin nhân sự'!B:B,0)) -> Sản xuất Video - Video Prodution | K17: =INDEX('6. data thông tin nhân sự'!D:D,MATCH('03. Chi tiết TS các bộ phận'!H17,'6. data thông tin nhân sự'!B:B,0)) -> Chính thức | M17: 46204 | N17: 45917 | O17: Đang sử dụng | Q17: MH048 - mới mua ngày 17/09/2025
A18: BP009 | B18: Bàn phím | E18: Khu vực BP Video | F18: Cái | G18: 1 | H18: 25011 | I18: =INDEX('6. data thông tin nhân sự'!C:C,MATCH('03. Chi tiết TS các bộ phận'!H18,'6. data thông tin nhân sự'!B:B,0)) -> Lê Công Hoàng | J18: =INDEX('6. data thông tin nhân sự'!G:G,MATCH('03. Chi tiết TS các bộ phận'!H18,'6. data thông tin nhân sự'!B:B,0)) -> Sản xuất Video - Video Prodution | K18: =INDEX('6. data thông tin nhân sự'!D:D,MATCH('03. Chi tiết TS các bộ phận'!H18,'6. data thông tin nhân sự'!B:B,0)) -> Chính thức | M18: 46204 | N18: =INDEX('6. data thông tin nhân sự'!N:N, MATCH('03. Chi tiết TS các bộ phận'!H18, '6. data thông tin nhân sự'!B:B,0)) -> 12/05/2025 | O18: Đang sử dụng
A19: PC009 | B19: PC | D19: - Chip: 12th Gen Intel(R) Core(TM) i9-12900K - Ram: 64 GB - Card màn hình: 12 GB - Ổ cứng: 20,92 TB | E19: Khu vực BP Video | F19: Cái | G19: 1 | H19: 25032 | I19: =INDEX('6. data thông tin nhân sự'!C:C,MATCH('03. Chi tiết TS các bộ phận'!H19,'6. data thông tin nhân sự'!B:B,0)) -> Nguyễn Ngọc Thắng | J19: =INDEX('6. data thông tin nhân sự'!G:G,MATCH('03. Chi tiết TS các bộ phận'!H19,'6. data thông tin nhân sự'!B:B,0)) -> Sản xuất Video - Video Prodution | K19: =INDEX('6. data thông tin nhân sự'!D:D,MATCH('03. Chi tiết TS các bộ phận'!H19,'6. data thông tin nhân sự'!B:B,0)) -> Chính thức | L19: VD_05 | M19: 46204 | N19: =INDEX('6. data thông tin nhân sự'!N:N, MATCH('03. Chi tiết TS các bộ phận'!H19, '6. data thông tin nhân sự'!B:B,0)) -> 25/09/2025 | O19: Đang sử dụng | R19: 25011- Lê Công Hoàng - từ ngày 8/8/2025 - trả ngày 19/09/2025
A20: MH049 | B20: Màn hình máy tính | C20: Dell | E20: Khu vực BP Video | F20: Cái | G20: 1 | H20: 25032 | I20: =INDEX('6. data thông tin nhân sự'!C:C,MATCH('03. Chi tiết TS các bộ phận'!H20,'6. data thông tin nhân sự'!B:B,0)) -> Nguyễn Ngọc Thắng | J20: =INDEX('6. data thông tin nhân sự'!G:G,MATCH('03. Chi tiết TS các bộ phận'!H20,'6. data thông tin nhân sự'!B:B,0)) -> Sản xuất Video - Video Prodution | K20: =INDEX('6. data thông tin nhân sự'!D:D,MATCH('03. Chi tiết TS các bộ phận'!H20,'6. data thông tin nhân sự'!B:B,0)) -> Chính thức | M20: 46204 | N20: =INDEX('6. data thông tin nhân sự'!N:N, MATCH('03. Chi tiết TS các bộ phận'!H20, '6. data thông tin nhân sự'!B:B,0)) -> 25/09/2025 | O20: Đang sử dụng
A21: MH043 | B21: Màn hình máy tính | C21: Dell | E21: Khu vực BP Video | F21: Cái | G21: 1 | H21: 25032 | I21: =INDEX('6. data thông tin nhân sự'!C:C,MATCH('03. Chi tiết TS các bộ phận'!H21,'6. data thông tin nhân sự'!B:B,0)) -> Nguyễn Ngọc Thắng | J21: =INDEX('6. data thông tin nhân sự'!G:G,MATCH('03. Chi tiết TS các bộ phận'!H21,'6. data thông tin nhân sự'!B:B,0)) -> Sản xuất Video - Video Prodution | K21: =INDEX('6. data thông tin nhân sự'!D:D,MATCH('03. Chi tiết TS các bộ phận'!H21,'6. data thông tin nhân sự'!B:B,0)) -> Chính thức | M21: 46204 | N21: =INDEX('6. data thông tin nhân sự'!N:N, MATCH('03. Chi tiết TS các bộ phận'!H21, '6. data thông tin nhân sự'!B:B,0)) -> 25/09/2025 | O21: Đang sử dụng | P21: Phiếu BH | Q21: MH043 - mới mua ngày 17/09/2025
A22: BP047 | B22: Bàn phím | C22: Dell | E22: Khu vực BP Video | F22: Cái | G22: 1 | H22: 25032 | I22: =INDEX('6. data thông tin nhân sự'!C:C,MATCH('03. Chi tiết TS các bộ phận'!H22,'6. data thông tin nhân sự'!B:B,0)) -> Nguyễn Ngọc Thắng | J22: =INDEX('6. data thông tin nhân sự'!G:G,MATCH('03. Chi tiết TS các bộ phận'!H22,'6. data thông tin nhân sự'!B:B,0)) -> Sản xuất Video - Video Prodution | K22: =INDEX('6. data thông tin nhân sự'!D:D,MATCH('03. Chi tiết TS các bộ phận'!H22,'6. data thông tin nhân sự'!B:B,0)) -> Chính thức | M22: 46204 | N22: =INDEX('6. data thông tin nhân sự'!N:N, MATCH('03. Chi tiết TS các bộ phận'!H22, '6. data thông tin nhân sự'!B:B,0)) -> 25/09/2025 | O22: Đang sử dụng
A23: KHÁC | B23: Ổ cứng | D23: - Ổ cứng gắn PC - HDD - Dung lượng: 15TB | E23: Khu vực BP Video | F23: Cái | G23: 1 | H23: 25032 | I23: =INDEX('6. data thông tin nhân sự'!C:C,MATCH('03. Chi tiết TS các bộ phận'!H23,'6. data thông tin nhân sự'!B:B,0)) -> Nguyễn Ngọc Thắng | J23: =INDEX('6. data thông tin nhân sự'!G:G,MATCH('03. Chi tiết TS các bộ phận'!H23,'6. data thông tin nhân sự'!B:B,0)) -> Sản xuất Video - Video Prodution | K23: =INDEX('6. data thông tin nhân sự'!D:D,MATCH('03. Chi tiết TS các bộ phận'!H23,'6. data thông tin nhân sự'!B:B,0)) -> Chính thức | M23: 46204 | N23: 46050 | O23: Đang sử dụng | Q23: Mua mới ngày 28/01/2026
A24: KHÁC | B24: Ổ cứng | D24: - Ổ cứng gắn PC - SSD - Dung lượng: 2TB | E24: Khu vực BP Video | F24: Cái | G24: 1 | H24: 25032 | I24: =INDEX('6. data thông tin nhân sự'!C:C,MATCH('03. Chi tiết TS các bộ phận'!H24,'6. data thông tin nhân sự'!B:B,0)) -> Nguyễn Ngọc Thắng | J24: =INDEX('6. data thông tin nhân sự'!G:G,MATCH('03. Chi tiết TS các bộ phận'!H24,'6. data thông tin nhân sự'!B:B,0)) -> Sản xuất Video - Video Prodution | K24: =INDEX('6. data thông tin nhân sự'!D:D,MATCH('03. Chi tiết TS các bộ phận'!H24,'6. data thông tin nhân sự'!B:B,0)) -> Chính thức | M24: 46204 | N24: 46050 | O24: Đang sử dụng | Q24: Mua mới ngày 28/01/2026
A25: KHÁC | B25: Ram | E25: Khu vực BP Video | F25: Cái | G25: 1 | H25: 25032 | I25: =INDEX('6. data thông tin nhân sự'!C:C,MATCH('03. Chi tiết TS các bộ phận'!H25,'6. data thông tin nhân sự'!B:B,0)) -> Nguyễn Ngọc Thắng | J25: =INDEX('6. data thông tin nhân sự'!G:G,MATCH('03. Chi tiết TS các bộ phận'!H25,'6. data thông tin nhân sự'!B:B,0)) -> Sản xuất Video - Video Prodution | K25: =INDEX('6. data thông tin nhân sự'!D:D,MATCH('03. Chi tiết TS các bộ phận'!H25,'6. data thông tin nhân sự'!B:B,0)) -> Chính thức | M25: 46204 | N25: 46050 | O25: Đang sử dụng | Q25: Mua mới ngày 28/01/2026, không dán mã do ram rất nhỏ và mỏng nếu dán sẽ khó lắp đặt vào máy
A26: MH010 | B26: Màn hình máy tính | C26: Asus Pro | E26: Khu vực BP Video | F26: Cái | G26: 1 | H26: 25045 | I26: =INDEX('6. data thông tin nhân sự'!C:C,MATCH('03. Chi tiết TS các bộ phận'!H26,'6. data thông tin nhân sự'!B:B,0)) -> Nguyễn Anh Tuấn | J26: =INDEX('6. data thông tin nhân sự'!G:G,MATCH('03. Chi tiết TS các bộ phận'!H26,'6. data thông tin nhân sự'!B:B,0)) -> Sản xuất Video - Video Prodution | K26: =INDEX('6. data thông tin nhân sự'!D:D,MATCH('03. Chi tiết TS các bộ phận'!H26,'6. data thông tin nhân sự'!B:B,0)) -> Chính thức | L26: VD_06 | M26: 46204 | N26: =INDEX('6. data thông tin nhân sự'!N:N, MATCH('03. Chi tiết TS các bộ phận'!H26, '6. data thông tin nhân sự'!B:B,0)) -> 16/12/2025 | O26: Đang sử dụng | P26: LINK | R26: Vũ Anh Duy sd tư 08/08/2025 đến ngày 15/12/2025
A27: MH040 | B27: Màn hình máy tính | C27: Asus Pro | E27: Khu vực BP Video | F27: Cái | G27: 1 | H27: 25045 | I27: =INDEX('6. data thông tin nhân sự'!C:C,MATCH('03. Chi tiết TS các bộ phận'!H27,'6. data thông tin nhân sự'!B:B,0)) -> Nguyễn Anh Tuấn | J27: =INDEX('6. data thông tin nhân sự'!G:G,MATCH('03. Chi tiết TS các bộ phận'!H27,'6. data thông tin nhân sự'!B:B,0)) -> Sản xuất Video - Video Prodution | K27: =INDEX('6. data thông tin nhân sự'!D:D,MATCH('03. Chi tiết TS các bộ phận'!H27,'6. data thông tin nhân sự'!B:B,0)) -> Chính thức | M27: 46204 | N27: =INDEX('6. data thông tin nhân sự'!N:N, MATCH('03. Chi tiết TS các bộ phận'!H27, '6. data thông tin nhân sự'!B:B,0)) -> 16/12/2025 | O27: Đang sử dụng | R27: Vũ Anh Duy sd tư 08/08/2025 đến ngày 15/12/2025
A28: PC051 | B28: PC | D28: - Chip: AMD Ryzen 9 9950X 16-Core Processor - Ram: 64 GB - Card màn hình: 14 GB - Ổ cứng: 7,28 TB | E28: Khu vực BP Video | F28: Cái | G28: 1 | H28: 25045 | I28: =INDEX('6. data thông tin nhân sự'!C:C,MATCH('03. Chi tiết TS các bộ phận'!H28,'6. data thông tin nhân sự'!B:B,0)) -> Nguyễn Anh Tuấn | J28: =INDEX('6. data thông tin nhân sự'!G:G,MATCH('03. Chi tiết TS các bộ phận'!H28,'6. data thông tin nhân sự'!B:B,0)) -> Sản xuất Video - Video Prodution | K28: =INDEX('6. data thông tin nhân sự'!D:D,MATCH('03. Chi tiết TS các bộ phận'!H28,'6. data thông tin nhân sự'!B:B,0)) -> Chính thức | M28: 46204 | N28: =INDEX('6. data thông tin nhân sự'!N:N, MATCH('03. Chi tiết TS các bộ phận'!H28, '6. data thông tin nhân sự'!B:B,0)) -> 16/12/2025 | O28: Đang sử dụng
A29: BP051 | B29: Bàn phím | E29: Khu vực BP Video | F29: Cái | G29: 1 | H29: 25045 | I29: =INDEX('6. data thông tin nhân sự'!C:C,MATCH('03. Chi tiết TS các bộ phận'!H29,'6. data thông tin nhân sự'!B:B,0)) -> Nguyễn Anh Tuấn | J29: =INDEX('6. data thông tin nhân sự'!G:G,MATCH('03. Chi tiết TS các bộ phận'!H29,'6. data thông tin nhân sự'!B:B,0)) -> Sản xuất Video - Video Prodution | K29: =INDEX('6. data thông tin nhân sự'!D:D,MATCH('03. Chi tiết TS các bộ phận'!H29,'6. data thông tin nhân sự'!B:B,0)) -> Chính thức | M29: 46204 | N29: =INDEX('6. data thông tin nhân sự'!N:N, MATCH('03. Chi tiết TS các bộ phận'!H29, '6. data thông tin nhân sự'!B:B,0)) -> 16/12/2025 | O29: Đang sử dụng
A30: CH051 | B30: Chuột | E30: Khu vực BP Video | F30: Cái | G30: 1 | H30: 25045 | I30: =INDEX('6. data thông tin nhân sự'!C:C,MATCH('03. Chi tiết TS các bộ phận'!H30,'6. data thông tin nhân sự'!B:B,0)) -> Nguyễn Anh Tuấn | J30: =INDEX('6. data thông tin nhân sự'!G:G,MATCH('03. Chi tiết TS các bộ phận'!H30,'6. data thông tin nhân sự'!B:B,0)) -> Sản xuất Video - Video Prodution | K30: =INDEX('6. data thông tin nhân sự'!D:D,MATCH('03. Chi tiết TS các bộ phận'!H30,'6. data thông tin nhân sự'!B:B,0)) -> Chính thức | M30: 46204 | N30: =INDEX('6. data thông tin nhân sự'!N:N, MATCH('03. Chi tiết TS các bộ phận'!H30, '6. data thông tin nhân sự'!B:B,0)) -> 16/12/2025 | O30: Đang sử dụng
A31: PC052 | B31: PC | D31: - Chip: AMD Ryzen 9 9950X 16-Core Processor - Ram: 64 GB - Card màn hình: 16 GB - Ổ cứng: 7,28 TB | E31: Khu vực BP Video | F31: Cái | G31: 1 | H31: 25046 | I31: =INDEX('6. data thông tin nhân sự'!C:C,MATCH('03. Chi tiết TS các bộ phận'!H31,'6. data thông tin nhân sự'!B:B,0)) -> Phùng Vân Anh | J31: =INDEX('6. data thông tin nhân sự'!G:G,MATCH('03. Chi tiết TS các bộ phận'!H31,'6. data thông tin nhân sự'!B:B,0)) -> Sản xuất Video - Video Prodution | K31: =INDEX('6. data thông tin nhân sự'!D:D,MATCH('03. Chi tiết TS các bộ phận'!H31,'6. data thông tin nhân sự'!B:B,0)) -> Chính thức | L31: VD_07 | M31: 46204 | N31: =INDEX('6. data thông tin nhân sự'!N:N, MATCH('03. Chi tiết TS các bộ phận'!H31, '6. data thông tin nhân sự'!B:B,0)) -> 16/12/2025 | O31: Đang sử dụng
A32: MH011 | B32: Màn hình máy tính | C32: Asus pro | E32: Khu vực BP Video | F32: Cái | G32: 1 | H32: 25046 | I32: =INDEX('6. data thông tin nhân sự'!C:C,MATCH('03. Chi tiết TS các bộ phận'!H32,'6. data thông tin nhân sự'!B:B,0)) -> Phùng Vân Anh | J32: =INDEX('6. data thông tin nhân sự'!G:G,MATCH('03. Chi tiết TS các bộ phận'!H32,'6. data thông tin nhân sự'!B:B,0)) -> Sản xuất Video - Video Prodution | K32: =INDEX('6. data thông tin nhân sự'!D:D,MATCH('03. Chi tiết TS các bộ phận'!H32,'6. data thông tin nhân sự'!B:B,0)) -> Chính thức | M32: 46204 | N32: =INDEX('6. data thông tin nhân sự'!N:N, MATCH('03. Chi tiết TS các bộ phận'!H32, '6. data thông tin nhân sự'!B:B,0)) -> 16/12/2025 | O32: Đang sử dụng | R32: 25026 Vũ Hoàng Duy sd tư 08/08/2025 đến ngày 15/12/2025
A33: MH009 | B33: Màn hình máy tính | C33: Asus pro | E33: Khu vực BP Video | F33: Cái | G33: 1 | H33: 25046 | I33: =INDEX('6. data thông tin nhân sự'!C:C,MATCH('03. Chi tiết TS các bộ phận'!H33,'6. data thông tin nhân sự'!B:B,0)) -> Phùng Vân Anh | J33: =INDEX('6. data thông tin nhân sự'!G:G,MATCH('03. Chi tiết TS các bộ phận'!H33,'6. data thông tin nhân sự'!B:B,0)) -> Sản xuất Video - Video Prodution | K33: =INDEX('6. data thông tin nhân sự'!D:D,MATCH('03. Chi tiết TS các bộ phận'!H33,'6. data thông tin nhân sự'!B:B,0)) -> Chính thức | M33: 46204 | N33: =INDEX('6. data thông tin nhân sự'!N:N, MATCH('03. Chi tiết TS các bộ phận'!H33, '6. data thông tin nhân sự'!B:B,0)) -> 16/12/2025 | O33: Đang sử dụng | R33: 25011- Lê Công Hoàng - từ ngày 8/8/2025 trả ngày 28/09/2025 | S33: "25026 Vũ Hoàng Duy Video Đang làm việc 08/08/2025 Đang sử dụng"
A36: II. TRUYỀN THÔNG - MARKETING
A37: OC-008 | B37: Ổ cứng | D37: ổ cứng rời 2TB | E37: Khu vực BP MKT | F37: cái | G37: 1 | H37: 20002 | I37: =INDEX('6. data thông tin nhân sự'!C:C,MATCH('03. Chi tiết TS các bộ phận'!H37,'6. data thông tin nhân sự'!B:B,0)) -> Đào Thị Thùy | J37: =INDEX('6. data thông tin nhân sự'!G:G,MATCH('03. Chi tiết TS các bộ phận'!H37,'6. data thông tin nhân sự'!B:B,0)) -> Truyền thông - Marketing | K37: =INDEX('6. data thông tin nhân sự'!D:D,MATCH('03. Chi tiết TS các bộ phận'!H37,'6. data thông tin nhân sự'!B:B,0)) -> Chính thức | L37: MKT_01 | M37: 46204 | N37: =INDEX('6. data thông tin nhân sự'!N:N, MATCH('03. Chi tiết TS các bộ phận'!H37, '6. data thông tin nhân sự'!B:B,0)) -> 25/05/2020 | O37: Đang sử dụng | R37: 25002 - Phạm Ngọc Anh - TP MKT quản lý - trả lại HCNS ngày 01/06/2026
A38: PC056 | B38: PC | D38: - Chip: AMD Ryzen 5 3500X 6-Core Processor - Ram: 16 GB - Card màn hình: 2 GB - Ổ cứng: 1,38 TB | E38: Khu vực BP MKT | F38: Cái | G38: 1 | H38: 20002 | I38: =INDEX('6. data thông tin nhân sự'!C:C,MATCH('03. Chi tiết TS các bộ phận'!H38,'6. data thông tin nhân sự'!B:B,0)) -> Đào Thị Thùy | J38: =INDEX('6. data thông tin nhân sự'!G:G,MATCH('03. Chi tiết TS các bộ phận'!H38,'6. data thông tin nhân sự'!B:B,0)) -> Truyền thông - Marketing | K38: =INDEX('6. data thông tin nhân sự'!D:D,MATCH('03. Chi tiết TS các bộ phận'!H38,'6. data thông tin nhân sự'!B:B,0)) -> Chính thức | M38: 45839 | N38: =INDEX('6. data thông tin nhân sự'!N:N, MATCH('03. Chi tiết TS các bộ phận'!H38, '6. data thông tin nhân sự'!B:B,0)) -> 25/05/2020 | O38: Đang sử dụng
A39: MH012 | B39: Màn hình máy tính | C39: Dell | E39: Khu vực BP MKT | F39: Cái | G39: 1 | H39: 20002 | I39: =INDEX('6. data thông tin nhân sự'!C:C,MATCH('03. Chi tiết TS các bộ phận'!H39,'6. data thông tin nhân sự'!B:B,0)) -> Đào Thị Thùy | J39: =INDEX('6. data thông tin nhân sự'!G:G,MATCH('03. Chi tiết TS các bộ phận'!H39,'6. data thông tin nhân sự'!B:B,0)) -> Truyền thông - Marketing | K39: =INDEX('6. data thông tin nhân sự'!D:D,MATCH('03. Chi tiết TS các bộ phận'!H39,'6. data thông tin nhân sự'!B:B,0)) -> Chính thức | M39: 45839 | N39: =INDEX('6. data thông tin nhân sự'!N:N, MATCH('03. Chi tiết TS các bộ phận'!H39, '6. data thông tin nhân sự'!B:B,0)) -> 25/05/2020 | O39: Đang sử dụng
A40: BP012 | B40: Bàn phím | C40: Dell | E40: Khu vực BP MKT | F40: Cái | G40: 1 | H40: 20002 | I40: =INDEX('6. data thông tin nhân sự'!C:C,MATCH('03. Chi tiết TS các bộ phận'!H40,'6. data thông tin nhân sự'!B:B,0)) -> Đào Thị Thùy | J40: =INDEX('6. data thông tin nhân sự'!G:G,MATCH('03. Chi tiết TS các bộ phận'!H40,'6. data thông tin nhân sự'!B:B,0)) -> Truyền thông - Marketing | K40: =INDEX('6. data thông tin nhân sự'!D:D,MATCH('03. Chi tiết TS các bộ phận'!H40,'6. data thông tin nhân sự'!B:B,0)) -> Chính thức | M40: 45839 | N40: =INDEX('6. data thông tin nhân sự'!N:N, MATCH('03. Chi tiết TS các bộ phận'!H40, '6. data thông tin nhân sự'!B:B,0)) -> 25/05/2020 | O40: Đang sử dụng
A41: CH012 | B41: Chuột | E41: Khu vực BP MKT | F41: Cái | G41: 1 | H41: 20002 | I41: =INDEX('6. data thông tin nhân sự'!C:C,MATCH('03. Chi tiết TS các bộ phận'!H41,'6. data thông tin nhân sự'!B:B,0)) -> Đào Thị Thùy | J41: =INDEX('6. data thông tin nhân sự'!G:G,MATCH('03. Chi tiết TS các bộ phận'!H41,'6. data thông tin nhân sự'!B:B,0)) -> Truyền thông - Marketing | K41: =INDEX('6. data thông tin nhân sự'!D:D,MATCH('03. Chi tiết TS các bộ phận'!H41,'6. data thông tin nhân sự'!B:B,0)) -> Chính thức | M41: 45839 | N41: =INDEX('6. data thông tin nhân sự'!N:N, MATCH('03. Chi tiết TS các bộ phận'!H41, '6. data thông tin nhân sự'!B:B,0)) -> 25/05/2020 | O41: Đang sử dụng
A42: PC057 | B42: PC | D42: - Chip: AMD Ryzen 5 3600 6-Core Processor - Ram: 16 GB - Card màn hình: 4 GB - Ổ cứng: 1,14 TB | E42: Khu vực BP MKT | F42: Cái | G42: 1 | H42: 22002 | I42: =INDEX('6. data thông tin nhân sự'!C:C,MATCH('03. Chi tiết TS các bộ phận'!H42,'6. data thông tin nhân sự'!B:B,0)) -> Ngô Khánh Vi | J42: =INDEX('6. data thông tin nhân sự'!G:G,MATCH('03. Chi tiết TS các bộ phận'!H42,'6. data thông tin nhân sự'!B:B,0)) -> Truyền thông - Marketing | K42: =INDEX('6. data thông tin nhân sự'!D:D,MATCH('03. Chi tiết TS các bộ phận'!H42,'6. data thông tin nhân sự'!B:B,0)) -> Chính thức | L42: MKT_02 | M42: 46204 | N42: =INDEX('6. data thông tin nhân sự'!N:N, MATCH('03. Chi tiết TS các bộ phận'!H42, '6. data thông tin nhân sự'!B:B,0)) -> 09/05/2022 | O42: Đang sử dụng
A43: MH013 | B43: Màn hình máy tính | C43: Dell | E43: Khu vực BP MKT | F43: Cái | G43: 1 | H43: 22002 | I43: =INDEX('6. data thông tin nhân sự'!C:C,MATCH('03. Chi tiết TS các bộ phận'!H43,'6. data thông tin nhân sự'!B:B,0)) -> Ngô Khánh Vi | J43: =INDEX('6. data thông tin nhân sự'!G:G,MATCH('03. Chi tiết TS các bộ phận'!H43,'6. data thông tin nhân sự'!B:B,0)) -> Truyền thông - Marketing | K43: =INDEX('6. data thông tin nhân sự'!D:D,MATCH('03. Chi tiết TS các bộ phận'!H43,'6. data thông tin nhân sự'!B:B,0)) -> Chính thức | M43: 46204 | N43: =INDEX('6. data thông tin nhân sự'!N:N, MATCH('03. Chi tiết TS các bộ phận'!H43, '6. data thông tin nhân sự'!B:B,0)) -> 09/05/2022 | O43: Đang sử dụng
...

Sheet 04. TH THEO LOẠI TS
B1: ổng | D1: Hanoi Head Office: 80 Nguyen Chi Thanh St., Lang Ward, Hanoi, Vietnam. Tel: + 84 24 3715 3303 / Hotline: +84 904 033 333/ 096 2577770 Website: newdaymedia.com.vn Email: info@newdaymedia.com.vn Facebook: Newday Media JSC
B2: TỔNG QUAN TÀI SẢN | I2: Laptop | J2: PC | K2: Màn hình máy tính | L2: Chuột | M2: Bàn phím | N2: Ổ cứng | O2: Khác | S2: Mã NV - Nguyễn Văn A - Sử dụng từ...đến...., bàn giao lại HCNS ngày....
I3: =COUNTIF(C:C, "Laptop") -> 7 | J3: =COUNTIF(C:C, "PC") -> 40 | K3: =COUNTIF(C:C, "Màn hình máy tính") -> 55 | L3: =COUNTIF(C:C, "Chuột ") -> 36 | M3: =COUNTIF(C:C, "Bàn phím") -> 32 | N3: =COUNTIF(C:C, "Ổ cứng") -> 11 | O3: =COUNTIF(B:B, "khác") -> 0
A4: STT | B4: MÃ TS | C4: TÊN TÀI SẢN | D4: HÃNG MUA | E4: THÔNG SỐ KĨ THUẬT | F4: VỊ TRÍ | G4: ĐƠN VỊ TÍNH | H4: SỐ LƯỢNG | I4: MÃ NHÂN VIÊN SD GẦN NHẤT | J4: HỌ TÊN NHÂN VIÊN SD GẦN NHẤT | K4: BỘ PHẬN | L4: TRẠNG THÁI NHÂN VIÊN ĐANG SD | M4: MÃ BIÊN BẢN BÀN GIAO | N4: NGÀY CẤP | O4: NGÀY HOÀN TRẢ | P4: TRẠNG THÁI TÀI SẢN | Q4: MÃ SỐ BẢO HÀNH | R4: GHI CHÚ | S4: NGƯỜI SỬ DỤNG 1 | T4: NGƯỜI SỬ DỤNG 2 | V4: NGƯỜI SỬ DỤNG 3 | W4: NGƯỜI SỬ DỤNG 4
B5: 1. LAPTOP
A6: 1 | B6: LT001 | C6: Laptop | D6: Lenovo | E6: - Ram: - Card màn hình: - Ổ cứng: - Màu sắc: | F6: Phòng MKT | G6: Cái | H6: 1 | I6: 26019 | J6: =INDEX('6. data thông tin nhân sự'!C:C, MATCH('04. TH THEO LOẠI TS'!I6, '6. data thông tin nhân sự'!B:B,0)) -> Vũ Thị Bích Ngọc | K6: =INDEX('6. data thông tin nhân sự'!G:G, MATCH('04. TH THEO LOẠI TS'!I6, '6. data thông tin nhân sự'!B:B,0)) -> Truyền thông - Marketing | L6: =INDEX('6. data thông tin nhân sự'!D:D, MATCH('04. TH THEO LOẠI TS'!I6, '6. data thông tin nhân sự'!B:B,0)) -> Chính thức | N6: 46204 | P6: Đang sử dụng | S6: Nguyễn Hồng Nhung sd từ ngày 08/08/2026 đến ngày 01/06/2026 bàn giao lại HCNS 01/06/2026
A7: 2 | B7: LT002 | C7: Laptop | D7: Máy tính Surface pro 7 | E7: - Ram - Card màn hình - Màu sắc: bạc | F7: Phòng Creative | G7: Cái | H7: 1 | I7: 25042 | J7: =INDEX('6. data thông tin nhân sự'!C:C, MATCH('04. TH THEO LOẠI TS'!I7, '6. data thông tin nhân sự'!B:B,0)) -> Nguyễn Thị Thu Giang | K7: =INDEX('6. data thông tin nhân sự'!G:G, MATCH('04. TH THEO LOẠI TS'!I7, '6. data thông tin nhân sự'!B:B,0)) -> Sáng tạo - Creative | L7: =INDEX('6. data thông tin nhân sự'!D:D, MATCH('04. TH THEO LOẠI TS'!I7, '6. data thông tin nhân sự'!B:B,0)) -> Chính thức | N7: 46204 | P7: Đang sử dụng | S7: Sếp Yến | T7: Mr. Hưng - TP Creative | U7: 20003 -Nguyễn Mạnh Hoàng - TP creative dùng - trả lại HCNS ngày 22/06/2026 | V7: 26005-Trần Thị Thanh Thùy-Creative- trả lại 08/07/2026
A8: 3 | B8: LT003 | C8: Laptop | D8: Máy tính Surface book 3 | E8: - Ram - Card màn hình - Màu sắc: bạc | F8: Phòng Creative | G8: Cái | H8: 1 | I8: 20003 | J8: =INDEX('6. data thông tin nhân sự'!C:C, MATCH('04. TH THEO LOẠI TS'!I8, '6. data thông tin nhân sự'!B:B,0)) -> Nguyễn Mạnh Hoàng | K8: =INDEX('6. data thông tin nhân sự'!G:G, MATCH('04. TH THEO LOẠI TS'!I8, '6. data thông tin nhân sự'!B:B,0)) -> Sáng tạo - Creative | L8: =INDEX('6. data thông tin nhân sự'!D:D, MATCH('04. TH THEO LOẠI TS'!I8, '6. data thông tin nhân sự'!B:B,0)) -> Chính thức | N8: 46204 | P8: Đang sử dụng | R8: Hoàng quản lý và máy dùng cho 2 bạn concept artist dùng khi đi công tác
A9: 4 | B9: LT004 | C9: Laptop | D9: Máy tính surface 11 pro | E9: - Ram - Card màn hình - Màu sắc: bạc | F9: Phòng Creative | G9: Cái | H9: 1 | I9: 20003 | J9: =INDEX('6. data thông tin nhân sự'!C:C, MATCH('04. TH THEO LOẠI TS'!I9, '6. data thông tin nhân sự'!B:B,0)) -> Nguyễn Mạnh Hoàng | K9: =INDEX('6. data thông tin nhân sự'!G:G, MATCH('04. TH THEO LOẠI TS'!I9, '6. data thông tin nhân sự'!B:B,0)) -> Sáng tạo - Creative | L9: =INDEX('6. data thông tin nhân sự'!D:D, MATCH('04. TH THEO LOẠI TS'!I9, '6. data thông tin nhân sự'!B:B,0)) -> Chính thức | M9: T06_2026_1517945 | N9: 46204 | P9: Đang sử dụng | R9: Mua mới ngày 10/06/2026 cấp cho Mạnh Hoàng | S9: Mạnh Hoàng - TP Creative
A10: 5 | B10: LT005 | C10: Laptop | D10: Máy tính Dell | E10: - Ram - Card màn hình - Màu sắc: | F10: Phòng Event | G10: Cái | H10: 1 | I10: 24001 | J10: =INDEX('6. data thông tin nhân sự'!C:C, MATCH('04. TH THEO LOẠI TS'!I10, '6. data thông tin nhân sự'!B:B,0)) -> Lê Lâm Cường | K10: =INDEX('6. data thông tin nhân sự'!G:G, MATCH('04. TH THEO LOẠI TS'!I10, '6. data thông tin nhân sự'!B:B,0)) -> Sự kiện - Event | L10: =INDEX('6. data thông tin nhân sự'!D:D, MATCH('04. TH THEO LOẠI TS'!I10, '6. data thông tin nhân sự'!B:B,0)) -> Nghỉ việc | N10: 46204 | P10: Đang sử dụng | R10: Cường quản lý và máy dùng chung cho phòng Event đi công tác
A11: 6 | B11: LT006 | C11: Laptop | D11: Máy tính Surface laptop | E11: - Ram - Card màn hình - Màu sắc: hồng | F11: Tồn kho | G11: Cái | H11: 1 | P11: Tồn kho | R11: 22/06/2026 Giang có báo hỏng không bật lên nguồn, tuy nhiên sau đó lại mở dùng đc | S11: Sếp Yến | T11: Mr. Hưng - TP Creative | U11: Trợ lý sếp Yến | V11: 20003 -Nguyễn Mạnh Hoàng - TP creative dùng - trả lại HCNS ngày 22/06/2026 | W11: 25042-Nguyễn Thị Thu Giang-Creative- trả lại HCNS 08/07/2026
A12: 7 | B12: LT007 | C12: Laptop | D12: Laptop Macbook Air M5 | E12: - Màu sắc: bạc | F12: Phòng Creative | G12: Cái | H12: 1 | I12: 21003 | J12: =INDEX('6. data thông tin nhân sự'!C:C, MATCH('04. TH THEO LOẠI TS'!I12, '6. data thông tin nhân sự'!B:B,0)) -> Đặng Đức Hoàng | K12: =INDEX('6. data thông tin nhân sự'!G:G, MATCH('04. TH THEO LOẠI TS'!I12, '6. data thông tin nhân sự'!B:B,0)) -> Sáng tạo - Creative | L12: =INDEX('6. data thông tin nhân sự'!D:D, MATCH('04. TH THEO LOẠI TS'!I12, '6. data thông tin nhân sự'!B:B,0)) -> Chính thức | N12: 46231 | P12: Đang sử dụng | R12: Mua mới ngày 17/07/2026 cấp cho Đức Hoàng
B13: 2. Ổ CỨNG
A14: 1 | B14: OC-001 | C14: Ổ cứng | E14: - Ổ cứng rời - HDD/SSD - Dung lượng: 2TB | F14: Khu vực BP Video | G14: cái | H14: 1 | K14: Video | L14: =INDEX('6. data thông tin nhân sự'!D:D, MATCH('04. TH THEO LOẠI TS'!I14, '6. data thông tin nhân sự'!B:B,0)) -> #N/A | N14: 46204 | P14: Tồn kho
A15: 2 | B15: OC-003 | C15: Ổ cứng | E15: - Ổ cứng rời - HDD - Dung lượng: 2TB | F15: Khu vực BP Video | G15: cái | H15: 1 | K15: Video | L15: =INDEX('6. data thông tin nhân sự'!D:D, MATCH('04. TH THEO LOẠI TS'!I15, '6. data thông tin nhân sự'!B:B,0)) -> #N/A | N15: 46204 | P15: Tồn kho
A16: 3 | B16: OC-004 | C16: Ổ cứng | E16: - 1TB - Ổ cứng rời | F16: Phòng HCNS | G16: cái | H16: 1 | P16: Tồn kho | R16: Đã chết ổ cứng | S16: 15001- Lê Văn Kha - TP event- bàn giao lại HCNS từ ngày 20/01/2026
A17: 4 | B17: OC-005 | C17: Ổ cứng | E17: - 1TB - Ổ cứng rời | F17: Phòng HCNS | G17: cái | H17: 1 | P17: Tồn kho | S17: 15001- Lê Văn Kha - TP event- bàn giao lại HCNS từ ngày 20/01/2026
A18: 5 | B18: OC-006 | C18: Ổ cứng | E18: - 1TB - Ổ cứng rời | F18: Phòng HCNS | G18: cái | H18: 1 | P18: Tồn kho | S18: 15001- Lê Văn Kha - TP event- bàn giao lại HCNS từ ngày 20/01/2026
A19: 6 | B19: OC-007 | C19: Ổ cứng | E19: - 1TB - Ổ cứng gắn máy | F19: Khu vực BP Creative | G19: cái | H19: 1 | I19: 20003 | J19: Nguyễn Mạnh Hoàng | K19: Creative | L19: =INDEX('6. data thông tin nhân sự'!D:D, MATCH('04. TH THEO LOẠI TS'!I19, '6. data thông tin nhân sự'!B:B,0)) -> Chính thức | N19: 46204 | P19: Đang sử dụng
A20: 7 | B20: OC-008 | C20: Ổ cứng | E20: - 2TB - Ổ cứng rời | F20: Khu vực BP MKT | G20: cái | H20: 1 | I20: 20002 | J20: Đào Thị Thùy | K20: MKT | L20: =INDEX('6. data thông tin nhân sự'!D:D, MATCH('04. TH THEO LOẠI TS'!I20, '6. data thông tin nhân sự'!B:B,0)) -> Chính thức | N20: 46204 | P20: Đang sử dụng | S20: 25002 - Phạm Ngọc Anh - TP MKT quản lý - trả lại HCNS ngày 01/06/2026
A21: 8 | B21: OC-009 | C21: Ổ cứng | D21: SSD Kingston | E21: - 1TB - Ổ cứng rời | F21: Khu vực BP Creative | G21: cái | H21: 1 | I21: 21003 | J21: Đặng Đức Hoàng | K21: Creative | L21: =INDEX('6. data thông tin nhân sự'!D:D, MATCH('04. TH THEO LOẠI TS'!I21, '6. data thông tin nhân sự'!B:B,0)) -> Chính thức | N21: 46204 | P21: Đang sử dụng | R21: Mua mới cấp cho Đức Hoàng ngày 15/01/2026, ổ cứng rời
A22: 9 | B22: OC-010 | C22: Ổ cứng | D22: SSD Kingston 1TB | E22: - 1TB - Ổ cứng gắn máy | F22: Phòng kế toán | G22: cái | H22: 1 | I22: 25039 | J22: Nguyễn Thị Thu Hoài | K22: TCKT | L22: =INDEX('6. data thông tin nhân sự'!D:D, MATCH('04. TH THEO LOẠI TS'!I22, '6. data thông tin nhân sự'!B:B,0)) -> Chính thức | N22: 46204 | P22: Đang sử dụng | R22: Mua mới cấp cho Thu Hoài kếtoán ngày 28/01/2026, ổ cứng cắm vào PC
A23: 10 | B23: OC -011 | C23: Ổ cứng | D23: SSD Kingston | E23: - Ổ cứng gắn PC - SSD - Dung lượng: 2TB | F23: Khu vực BP Video | G23: cái | H23: 1 | I23: 25032 | J23: Nguyễn Ngọc Thắng | K23: Video | L23: =INDEX('6. data thông tin nhân sự'!D:D, MATCH('04. TH THEO LOẠI TS'!I23, '6. data thông tin nhân sự'!B:B,0)) -> Chính thức | N23: 46204 | P23: Đang sử dụng | R23: Mua mới cấp cho Thắng Video ngày 28/01/2026, ổ cứng cắm vào PC
B24: 3. PC
A25: 1 | B25: PC008 | C25: PC | F25: Khu vực BP Video | G25: Cái | H25: 1 | K25: =INDEX('6. data thông tin nhân sự'!G:G, MATCH('04. TH THEO LOẠI TS'!I25, '6. data thông tin nhân sự'!B:B,0)) -> #N/A | L25: =INDEX('6. data thông tin nhân sự'!D:D, MATCH('04. TH THEO LOẠI TS'!I25, '6. data thông tin nhân sự'!B:B,0)) -> #N/A | N25: 46204 | P25: Tồn kho | R25: 5T dung lượng ổ cứng, 30T ổ cứng cắm vào,3 ổ cứng di động ( 2T/cái)
A26: 2 | B26: PC058 | C26: PC | E26: - Chip: AMD Ryzen 5 2600 Six-Core Processor - Ram: 16 GB - Card màn hình: 3 GB - Ổ cứng: 112 GB | F26: Khu vực BP Video | G26: Cái | H26: 1 | I26: 26014 | J26: =INDEX('6. data thông tin nhân sự'!C:C, MATCH('04. TH THEO LOẠI TS'!I26, '6. data thông tin nhân sự'!B:B,0)) -> Nguyễn Thị Thùy Linh | K26: =INDEX('6. data thông tin nhân sự'!G:G, MATCH('04. TH THEO LOẠI TS'!I26, '6. data thông tin nhân sự'!B:B,0)) -> Sản xuất Video - Video Prodution | L26: =INDEX('6. data thông tin nhân sự'!D:D, MATCH('04. TH THEO LOẠI TS'!I26, '6. data thông tin nhân sự'!B:B,0)) -> Nghỉ việc | N26: 46204 | P26: Tồn kho
A27: 3 | B27: PC010 | C27: PC | E27: - Chip: AMD Ryzen 9 9900X 12-Core Processor - Ram: 128 GB - Card màn hình: 18 GB - Ổ cứng: 5.46 TB | F27: Khu vực BP Video | G27: Cái | H27: 1 | I27: 24004 | J27: =INDEX('6. data thông tin nhân sự'!C:C, MATCH('04. TH THEO LOẠI TS'!I27, '6. data thông tin nhân sự'!B:B,0)) -> Vũ Anh Duy | K27: =INDEX('6. data thông tin nhân sự'!G:G, MATCH('04. TH THEO LOẠI TS'!I27, '6. data thông tin nhân sự'!B:B,0)) -> Sản xuất Video - Video Prodution | L27: =INDEX('6. data thông tin nhân sự'!D:D, MATCH('04. TH THEO LOẠI TS'!I27, '6. data thông tin nhân sự'!B:B,0)) -> Chính thức | N27: 46202 | P27: Đang sử dụng
A28: 4 | B28: PC011 | C28: PC | E28: - Chip: 12th Gen Intel(R) Core(TM) i9-12900K - Ram: 32 GB - Card màn hình: 12 GB - Ổ cứng: 15,01 TB | F28: Khu vực BP Video | G28: Cái | H28: 1 | I28: 25026 | J28: =INDEX('6. data thông tin nhân sự'!C:C, MATCH('04. TH THEO LOẠI TS'!I28, '6. data thông tin nhân sự'!B:B,0)) -> Vũ Hoàng Duy | K28: =INDEX('6. data thông tin nhân sự'!G:G, MATCH('04. TH THEO LOẠI TS'!I28, '6. data thông tin nhân sự'!B:B,0)) -> Sản xuất Video - Video Prodution | L28: =INDEX('6. data thông tin nhân sự'!D:D, MATCH('04. TH THEO LOẠI TS'!I28, '6. data thông tin nhân sự'!B:B,0)) -> Chính thức | N28: 46204 | P28: Đang sử dụng
A29: 5 | B29: PC047 | C29: PC | E29: - AMD Ryzen 9 9950X 16-Core Processor - Ram: 128 GB - Card màn hình: 16 GB - Ổ cứng: 7,28 TB | F29: Khu vực BP Video | G29: Cái | H29: 1 | I29: 25011 | J29: =INDEX('6. data thông tin nhân sự'!C:C, MATCH('04. TH THEO LOẠI TS'!I29, '6. data thông tin nhân sự'!B:B,0)) -> Lê Công Hoàng | K29: =INDEX('6. data thông tin nhân sự'!G:G, MATCH('04. TH THEO LOẠI TS'!I29, '6. data thông tin nhân sự'!B:B,0)) -> Sản xuất Video - Video Prodution | L29: =INDEX('6. data thông tin nhân sự'!D:D, MATCH('04. TH THEO LOẠI TS'!I29, '6. data thông tin nhân sự'!B:B,0)) -> Chính thức | N29: 46204 | P29: Đang sử dụng | Q29: Phiếu BH | R29: PC047 - mới mua ngày. 17/09/2025
A30: 6 | B30: PC009 | C30: PC | E30: - Chip: 12th Gen Intel(R) Core(TM) i9-12900K - Ram: 64 GB - Card màn hình: 12 GB - Ổ cứng: 20,92 TB | F30: Khu vực BP Video | G30: Cái | H30: 1 | I30: 25032 | J30: =INDEX('6. data thông tin nhân sự'!C:C, MATCH('04. TH THEO LOẠI TS'!I30, '6. data thông tin nhân sự'!B:B,0)) -> Nguyễn Ngọc Thắng | K30: =INDEX('6. data thông tin nhân sự'!G:G, MATCH('04. TH THEO LOẠI TS'!I30, '6. data thông tin nhân sự'!B:B,0)) -> Sản xuất Video - Video Prodution | L30: =INDEX('6. data thông tin nhân sự'!D:D, MATCH('04. TH THEO LOẠI TS'!I30, '6. data thông tin nhân sự'!B:B,0)) -> Chính thức | N30: 46204 | P30: Đang sử dụng | S30: 25011- Lê Công Hoàng - từ ngày 8/8/2025 - trả ngày 19/09/2025
A31: 7 | B31: PC051 | C31: PC | E31: - Chip: AMD Ryzen 9 9950X 16-Core Processor - Ram: 64 GB - Card màn hình: 14 GB - Ổ cứng: 7,28 TB | F31: Khu vực BP Video | G31: Cái | H31: 1 | I31: 25045 | J31: =INDEX('6. data thông tin nhân sự'!C:C, MATCH('04. TH THEO LOẠI TS'!I31, '6. data thông tin nhân sự'!B:B,0)) -> Nguyễn Anh Tuấn | K31: =INDEX('6. data thông tin nhân sự'!G:G, MATCH('04. TH THEO LOẠI TS'!I31, '6. data thông tin nhân sự'!B:B,0)) -> Sản xuất Video - Video Prodution | L31: =INDEX('6. data thông tin nhân sự'!D:D, MATCH('04. TH THEO LOẠI TS'!I31, '6. data thông tin nhân sự'!B:B,0)) -> Chính thức | N31: 46204 | P31: Đang sử dụng
A32: 8 | B32: PC052 | C32: PC | E32: - Chip: AMD Ryzen 9 9950X 16-Core Processor - Ram: 64 GB - Card màn hình: 16 GB - Ổ cứng: 7,28 TB | F32: Khu vực BP Video | G32: Cái | H32: 1 | I32: 25046 | J32: =INDEX('6. data thông tin nhân sự'!C:C, MATCH('04. TH THEO LOẠI TS'!I32, '6. data thông tin nhân sự'!B:B,0)) -> Phùng Vân Anh | K32: =INDEX('6. data thông tin nhân sự'!G:G, MATCH('04. TH THEO LOẠI TS'!I32, '6. data thông tin nhân sự'!B:B,0)) -> Sản xuất Video - Video Prodution | L32: =INDEX('6. data thông tin nhân sự'!D:D, MATCH('04. TH THEO LOẠI TS'!I32, '6. data thông tin nhân sự'!B:B,0)) -> Chính thức | N32: 46204 | P32: Đang sử dụng
A33: 9 | B33: PC056 | C33: PC | E33: - Chip: AMD Ryzen 5 3500X 6-Core Processor - Ram: 16 GB - Card màn hình: 2 GB - Ổ cứng: 1,38 TB | F33: Khu vực BP MKT | G33: Cái | H33: 1 | I33: 20002 | J33: =INDEX('6. data thông tin nhân sự'!C:C, MATCH('04. TH THEO LOẠI TS'!I33, '6. data thông tin nhân sự'!B:B,0)) -> Đào Thị Thùy | K33: =INDEX('6. data thông tin nhân sự'!G:G, MATCH('04. TH THEO LOẠI TS'!I33, '6. data thông tin nhân sự'!B:B,0)) -> Truyền thông - Marketing | L33: =INDEX('6. data thông tin nhân sự'!D:D, MATCH('04. TH THEO LOẠI TS'!I33, '6. data thông tin nhân sự'!B:B,0)) -> Chính thức | N33: 45839 | P33: Đang sử dụng
A34: 10 | B34: PC057 | C34: PC | E34: - Chip: AMD Ryzen 5 3600 6-Core Processor - Ram: 16 GB - Card màn hình: 4 GB - Ổ cứng: 1,14 TB | F34: Khu vực BP MKT | G34: Cái | H34: 1 | I34: 22002 | J34: =INDEX('6. data thông tin nhân sự'!C:C, MATCH('04. TH THEO LOẠI TS'!I34, '6. data thông tin nhân sự'!B:B,0)) -> Ngô Khánh Vi | K34: =INDEX('6. data thông tin nhân sự'!G:G, MATCH('04. TH THEO LOẠI TS'!I34, '6. data thông tin nhân sự'!B:B,0)) -> Truyền thông - Marketing | L34: =INDEX('6. data thông tin nhân sự'!D:D, MATCH('04. TH THEO LOẠI TS'!I34, '6. data thông tin nhân sự'!B:B,0)) -> Chính thức | N34: 46204 | P34: Đang sử dụng
A35: 11 | B35: PC036 | C35: PC | E35: - Chip: Intel(R) Core(TM) i7-10700 CPU@ 2.90GHz - Ram: 16 GB - Card màn hình: 128 MB - Ổ cứng: 1.14 TB | F35: Khu vực BP Creative | G35: Cái | H35: 1 | I35: 26023 | J35: =INDEX('6. data thông tin nhân sự'!C:C, MATCH('04. TH THEO LOẠI TS'!I35, '6. data thông tin nhân sự'!B:B,0)) -> Lê Đức Minh | K35: =INDEX('6. data thông tin nhân sự'!G:G, MATCH('04. TH THEO LOẠI TS'!I35, '6. data thông tin nhân sự'!B:B,0)) -> Sáng tạo - Creative | L35: =INDEX('6. data thông tin nhân sự'!D:D, MATCH('04. TH THEO LOẠI TS'!I35, '6. data thông tin nhân sự'!B:B,0)) -> Thử việc | N35: 46237 | P35: Đang sử dụng | S35: Nguyễn Chí Hiếu sd từ ngày 14/07/2026 đến ngày 03/08/2026 bàn giao lại HCNS 01/06/2026
A36: 12 | B36: PC015 | C36: PC | E36: - Chip: Intel(R) Core(TM) i5-10400 CPU @ 2.90GHz - Ram: 16 GB - Card màn hình: 128 MB - Ổ cứng: 1.13 TB | F36: Khu vực BP Creative | G36: Cái | H36: 1 | I36: 24003 | J36: =INDEX('6. data thông tin nhân sự'!C:C, MATCH('04. TH THEO LOẠI TS'!I36, '6. data thông tin nhân sự'!B:B,0)) -> Nguyễn Thị Hà Giang | K36: =INDEX('6. data thông tin nhân sự'!G:G, MATCH('04. TH THEO LOẠI TS'!I36, '6. data thông tin nhân sự'!B:B,0)) -> Sáng tạo - Creative | L36: =INDEX('6. data thông tin nhân sự'!D:D, MATCH('04. TH THEO LOẠI TS'!I36, '6. data thông tin nhân sự'!B:B,0)) -> Chính thức | N36: 46217 | P36: Đang sử dụng | S36: Đặng Đức Hoàng Creative sd từ ngày 08/08/2025 đến ngày 24/06/2026 bàn giao lại cho HCNS
A37: 13 | B37: PC033 | C37: PC | E37: - Chip: Intel(R) Core(TM) i7-10700 CPU @ 2.90GHz - Ram: 16 GB - Card màn hình: 128 MB - Ổ cứng: 2.26 TB | F37: Khu vực BP Creative | G37: Cái | H37: 1 | I37: 26001 | J37: =INDEX('6. data thông tin nhân sự'!C:C, MATCH('04. TH THEO LOẠI TS'!I37, '6. data thông tin nhân sự'!B:B,0)) -> Tô Hồng Đức | K37: =INDEX('6. data thông tin nhân sự'!G:G, MATCH('04. TH THEO LOẠI TS'!I37, '6. data thông tin nhân sự'!B:B,0)) -> Sáng tạo - Creative | L37: =INDEX('6. data thông tin nhân sự'!D:D, MATCH('04. TH THEO LOẠI TS'!I37, '6. data thông tin nhân sự'!B:B,0)) -> Chính thức | N37: 46217 | P37: Đang sử dụng
A38: 14 | B38: PC021 | C38: PC | E38: - Chip: Intel(R) Core(TM) i7-8700 CPU @ 3.20GHz - Ram: 16 GB - Card màn hình: 3 GB - Ổ cứng: 1.14 TB | F38: Khu vực BP Event | G38: Cái | H38: 1 | I38: 24001 | J38: =INDEX('6. data thông tin nhân sự'!C:C, MATCH('04. TH THEO LOẠI TS'!I38, '6. data thông tin nhân sự'!B:B,0)) -> Lê Lâm Cường | K38: =INDEX('6. data thông tin nhân sự'!G:G, MATCH('04. TH THEO LOẠI TS'!I38, '6. data thông tin nhân sự'!B:B,0)) -> Sự kiện - Event | L38: =INDEX('6. data thông tin nhân sự'!D:D, MATCH('04. TH THEO LOẠI TS'!I38, '6. data thông tin nhân sự'!B:B,0)) -> Nghỉ việc | N38: 46204 | P38: Đang sử dụng
A39: 15 | B39: PC050 | C39: PC | E39: - Chip: Intel(R) Core(TM) i5-14600KF - Ram: 32 GB - Card màn hình: 12 GB - Ổ cứng: 954 GB | F39: Khu vực BP Event | G39: Cái | H39: 1 | I39: 22001 | J39: =INDEX('6. data thông tin nhân sự'!C:C, MATCH('04. TH THEO LOẠI TS'!I39, '6. data thông tin nhân sự'!B:B,0)) -> Bùi Xuân Dân | K39: =INDEX('6. data thông tin nhân sự'!G:G, MATCH('04. TH THEO LOẠI TS'!I39, '6. data thông tin nhân sự'!B:B,0)) -> Sự kiện - Event | L39: =INDEX('6. data thông tin nhân sự'!D:D, MATCH('04. TH THEO LOẠI TS'!I39, '6. data thông tin nhân sự'!B:B,0)) -> Chính thức | N39: 46204 | P39: Đang sử dụng | Q39: Phiếu BH | R39: PC050 - mới mua ngày 1/10/2025
